
import traceback

try:
    raise ValueError('invalid value')
except :
    print(traceback.format_exc())
